2025-03-24 14:06:30,977 INFO    MainThread:9864 [wandb_setup.py:_flush():67] Current SDK version is 0.19.8
2025-03-24 14:06:30,977 INFO    MainThread:9864 [wandb_setup.py:_flush():67] Configure stats pid to 9864
2025-03-24 14:06:30,977 INFO    MainThread:9864 [wandb_setup.py:_flush():67] Loading settings from C:\Users\q675000\.config\wandb\settings
2025-03-24 14:06:30,977 INFO    MainThread:9864 [wandb_setup.py:_flush():67] Loading settings from C:\Users\q675000\hvs_temperatur_prediction\wandb\settings
2025-03-24 14:06:30,977 INFO    MainThread:9864 [wandb_setup.py:_flush():67] Loading settings from environment variables
2025-03-24 14:06:30,978 INFO    MainThread:9864 [wandb_init.py:setup_run_log_directory():647] Logging user logs to C:\Users\q675000\hvs_temperatur_prediction\wandb\run-20250324_140630-p6xrnjyh\logs\debug.log
2025-03-24 14:06:30,979 INFO    MainThread:9864 [wandb_init.py:setup_run_log_directory():648] Logging internal logs to C:\Users\q675000\hvs_temperatur_prediction\wandb\run-20250324_140630-p6xrnjyh\logs\debug-internal.log
2025-03-24 14:06:30,979 INFO    MainThread:9864 [wandb_init.py:init():761] calling init triggers
2025-03-24 14:06:30,979 INFO    MainThread:9864 [wandb_init.py:init():766] wandb.init called with sweep_config: {}
config: {'epochs': 1000, 'batch_size': 32, 'learning_rate': 0.001, '_wandb': {}}
2025-03-24 14:06:30,979 INFO    MainThread:9864 [wandb_init.py:init():784] starting backend
2025-03-24 14:06:30,979 INFO    MainThread:9864 [wandb_init.py:init():788] sending inform_init request
2025-03-24 14:06:31,035 INFO    MainThread:9864 [backend.py:_multiprocessing_setup():101] multiprocessing start_methods=spawn, using: spawn
2025-03-24 14:06:31,036 INFO    MainThread:9864 [wandb_init.py:init():798] backend started and connected
2025-03-24 14:06:31,037 INFO    MainThread:9864 [wandb_init.py:init():891] updated telemetry
2025-03-24 14:06:31,037 INFO    MainThread:9864 [wandb_init.py:init():915] communicating run to backend with 90.0 second timeout
2025-03-24 14:06:31,272 INFO    Thread-4 (wrapped_target):9864 [retry.py:__call__():175] Retry attempt failed:
Traceback (most recent call last):
  File "C:\Users\q675000\AppData\Local\anaconda3\envs\exploration\Lib\site-packages\urllib3\connectionpool.py", line 775, in urlopen
    self._prepare_proxy(conn)
  File "C:\Users\q675000\AppData\Local\anaconda3\envs\exploration\Lib\site-packages\urllib3\connectionpool.py", line 1044, in _prepare_proxy
    conn.connect()
  File "C:\Users\q675000\AppData\Local\anaconda3\envs\exploration\Lib\site-packages\urllib3\connection.py", line 710, in connect
    self._tunnel()
  File "C:\Users\q675000\AppData\Local\anaconda3\envs\exploration\Lib\http\client.py", line 979, in _tunnel
    raise OSError(f"Tunnel connection failed: {code} {message.strip()}")
OSError: Tunnel connection failed: 501 Not Implemented

The above exception was the direct cause of the following exception:

urllib3.exceptions.ProxyError: ('Unable to connect to proxy', OSError('Tunnel connection failed: 501 Not Implemented'))

The above exception was the direct cause of the following exception:

Traceback (most recent call last):
  File "C:\Users\q675000\AppData\Local\anaconda3\envs\exploration\Lib\site-packages\requests\adapters.py", line 667, in send
    resp = conn.urlopen(
           ^^^^^^^^^^^^^
  File "C:\Users\q675000\AppData\Local\anaconda3\envs\exploration\Lib\site-packages\urllib3\connectionpool.py", line 843, in urlopen
    retries = retries.increment(
              ^^^^^^^^^^^^^^^^^^
  File "C:\Users\q675000\AppData\Local\anaconda3\envs\exploration\Lib\site-packages\urllib3\util\retry.py", line 519, in increment
    raise MaxRetryError(_pool, url, reason) from reason  # type: ignore[arg-type]
    ^^^^^^^^^^^^^^^^^^^^^^^^^^^^^^^^^^^^^^^^^^^^^^^^^^^
urllib3.exceptions.MaxRetryError: HTTPSConnectionPool(host='api.wandb.ai', port=443): Max retries exceeded with url: /graphql (Caused by ProxyError('Unable to connect to proxy', OSError('Tunnel connection failed: 501 Not Implemented')))

During handling of the above exception, another exception occurred:

Traceback (most recent call last):
  File "C:\Users\q675000\AppData\Local\anaconda3\envs\exploration\Lib\site-packages\wandb\sdk\lib\retry.py", line 134, in __call__
    result = self._call_fn(*args, **kwargs)
             ^^^^^^^^^^^^^^^^^^^^^^^^^^^^^^
  File "C:\Users\q675000\AppData\Local\anaconda3\envs\exploration\Lib\site-packages\wandb\sdk\internal\internal_api.py", line 398, in execute
    return self.client.execute(*args, **kwargs)  # type: ignore
           ^^^^^^^^^^^^^^^^^^^^^^^^^^^^^^^^^^^^
  File "C:\Users\q675000\AppData\Local\anaconda3\envs\exploration\Lib\site-packages\wandb\vendor\gql-0.2.0\wandb_gql\client.py", line 52, in execute
    result = self._get_result(document, *args, **kwargs)
             ^^^^^^^^^^^^^^^^^^^^^^^^^^^^^^^^^^^^^^^^^^^
  File "C:\Users\q675000\AppData\Local\anaconda3\envs\exploration\Lib\site-packages\wandb\vendor\gql-0.2.0\wandb_gql\client.py", line 60, in _get_result
    return self.transport.execute(document, *args, **kwargs)
           ^^^^^^^^^^^^^^^^^^^^^^^^^^^^^^^^^^^^^^^^^^^^^^^^^
  File "C:\Users\q675000\AppData\Local\anaconda3\envs\exploration\Lib\site-packages\wandb\sdk\lib\gql_request.py", line 58, in execute
    request = self.session.post(self.url, **post_args)
              ^^^^^^^^^^^^^^^^^^^^^^^^^^^^^^^^^^^^^^^^
  File "C:\Users\q675000\AppData\Local\anaconda3\envs\exploration\Lib\site-packages\requests\sessions.py", line 637, in post
    return self.request("POST", url, data=data, json=json, **kwargs)
           ^^^^^^^^^^^^^^^^^^^^^^^^^^^^^^^^^^^^^^^^^^^^^^^^^^^^^^^^^
  File "C:\Users\q675000\AppData\Local\anaconda3\envs\exploration\Lib\site-packages\requests\sessions.py", line 589, in request
    resp = self.send(prep, **send_kwargs)
           ^^^^^^^^^^^^^^^^^^^^^^^^^^^^^^
  File "C:\Users\q675000\AppData\Local\anaconda3\envs\exploration\Lib\site-packages\requests\sessions.py", line 703, in send
    r = adapter.send(request, **kwargs)
        ^^^^^^^^^^^^^^^^^^^^^^^^^^^^^^^
  File "C:\Users\q675000\AppData\Local\anaconda3\envs\exploration\Lib\site-packages\requests\adapters.py", line 694, in send
    raise ProxyError(e, request=request)
requests.exceptions.ProxyError: HTTPSConnectionPool(host='api.wandb.ai', port=443): Max retries exceeded with url: /graphql (Caused by ProxyError('Unable to connect to proxy', OSError('Tunnel connection failed: 501 Not Implemented')))
